Workbook
Name dnevnik_header_0: Даты_темы!$C$1:$C$3

Sheet Баллы, оценки
A1: Фамилия Имя | B1: 1 | C1: 2 | D1: 3 | E1: 4 | F1: оценка 1 | G1: 5 | H1: 6 | I1: 7 | J1: 8 | K1: оценка 2 | L1: 9 | M1: 10 | N1: 11 | O1: 12 | P1: оценка 3 | Q1: 13 | R1: 14 | S1: 15 | T1: 16 | U1: оценка 4 | V1: ПР1_ур.17 | W1: ПР2_ур.18 | X1: ПР3_ур.19 | Y1: ПР4_ур.20 | Z1: ПР5_ур.21 | AA1: ПР6_ур.22 | AB1: ПР7_ур.23 | AC1: ЛР 1_ур.24 | AD1: ЛР 2_ур.25 | AE1: ЛР 3_ур.26 | AF1: ЛР 4_ур.27 | AG1: 28 | AH1: 29 | AI1: 30 | AJ1: 31 | AK1: 32 | AL1: итог в баллах | AM1: кол-пропусков | AN1: доп.задания | AQ1: ДЗ_ER-модель в тет. | AR1: ДЗ_БД Успев | AS1: ДЗ БД своя+кл.раб | AT1: ДЗ | AU1: Диф. зачет_33
B2: 45905 | C2: 45907 | D2: 45912 | E2: 45914 | F2: 45914 | G2: 45921 | H2: 45923 | I2: 45926 | J2: 45933 | K2: 45935 | L2: 45935 | M2: 45935 | N2: 45936 | O2: 45961 | P2: 45961 | Q2: 45968 | R2: 45970 | S2: 45977 | T2: 45989 | U2: 46354 | V2: 45919 | W2: 45947 | X2: 45954 | Y2: 45975 | Z2: 45982 | AA2: 45984 | AB2: 45996 | AC2: 12.10/15.10 | AD2: 19.10/22.10.2025 | AE2: 26.10/29.10 | AF2: 02.11/05.11 | AG2: 45991 | AH2: 45998 | AI2: 46003 | AJ2: 46005 | AK2: 46010 | AL2: 46012 | AM2: 32 урока | AN2: STEPIC | AO2: доп.баллы | AP2: доп.баллы | AQ2: 46272 | AR2: 46291 | AS2: 46298 | AU2: 46012
A3: Матвеев Никита | B3: 0.5 | C3: 0.5 | D3: 0.8 | E3: 2.5 | F3: =IF(SUM('Баллы, оценки'!$B19:$E19)>=3.5,5,IF(AND(SUM('Баллы, оценки'!$B19:$E19)>2.5,(SUM('Баллы, оценки'!$B19:$E19)<3.5)),4,IF(AND(SUM('Баллы, оценки'!$B19:$E19)<=2.5,(SUM('Баллы, оценки'!$B19:$E19)>1.5)),3,2))) -> 3 | G3: 0.5 | H3: 0.5 | I3: 0.5 | J3: 2.5 | K3: =IF(SUM('Баллы, оценки'!$G19:$J19)>=3.5,5,IF(AND(SUM('Баллы, оценки'!$G19:$J19)>2.5,(SUM('Баллы, оценки'!$G19:$J19)<3.5)),4,IF(AND(SUM('Баллы, оценки'!$G19:$J19)<=2.5,(SUM('Баллы, оценки'!$G19:$J19)>1.5)),3,2))) -> 5 | L3: 0.5 | M3: 0.5 | N3: 0.5 | P3: =IF(SUM('Баллы, оценки'!$L19:$O19)>=3.5,5,IF(AND(SUM('Баллы, оценки'!$L19:$O19)>2.5,(SUM('Баллы, оценки'!$L19:$O19)<3.5)),4,IF(AND(SUM('Баллы, оценки'!$L19:$O19)<=2.5,(SUM('Баллы, оценки'!$L19:$O19)>1.5)),3,2))) -> 2 | U3: =IF(SUM('Баллы, оценки'!$Q19:$T19)>=3.5,5,IF(AND(SUM('Баллы, оценки'!$Q19:$T19)>2.5,(SUM('Баллы, оценки'!$Q19:$T19)<3.5)),4,IF(AND(SUM('Баллы, оценки'!$Q19:$T19)<=2.5,(SUM('Баллы, оценки'!$Q19:$T19)>1.5)),3,2))) -> 2 | V3: 0.5 | AL3: =SUM('Баллы, оценки'!$B19:$E19,'Баллы, оценки'!$G19:$J19,'Баллы, оценки'!$L19:$O19,'Баллы, оценки'!$Q19:$T19,'Баллы, оценки'!$V19:$AF19,AH3:AK3) -> 7.5 | AM3: =32-COUNTA(B3:E3,G3:I3,L3:O3,Q3:T3,V3:AF3,AH3:AK3) -> 21 | AR3: 4 | AU3: =IF(AND('Баллы, оценки'!$AL19<=38,'Баллы, оценки'!$AL19>=31),5,IF(AND('Баллы, оценки'!$AL19<=30.9,'Баллы, оценки'!$AL19>=25),4,IF(AND('Баллы, оценки'!$AL19<=24.9,'Баллы, оценки'!$AL19>=21),3,н/а))) -> #NAME?
A4: Матвеев Иван | B4: 0.5 | C4: 0.5 | D4: 0.7 | E4: 2.5 | F4: =IF(SUM('Баллы, оценки'!$B18:$E18)>=3.5,5,IF(AND(SUM('Баллы, оценки'!$B18:$E18)>2.5,(SUM('Баллы, оценки'!$B18:$E18)<3.5)),4,IF(AND(SUM('Баллы, оценки'!$B18:$E18)<=2.5,(SUM('Баллы, оценки'!$B18:$E18)>1.5)),3,2))) -> 5 | G4: 0.5 | H4: 0.5 | I4: 0.5 | J4: 2.5 | K4: =IF(SUM('Баллы, оценки'!$G18:$J18)>=3.5,5,IF(AND(SUM('Баллы, оценки'!$G18:$J18)>2.5,(SUM('Баллы, оценки'!$G18:$J18)<3.5)),4,IF(AND(SUM('Баллы, оценки'!$G18:$J18)<=2.5,(SUM('Баллы, оценки'!$G18:$J18)>1.5)),3,2))) -> 3 | L4: 0.5 | M4: 0.5 | N4: 0.5 | P4: =IF(SUM('Баллы, оценки'!$L18:$O18)>=3.5,5,IF(AND(SUM('Баллы, оценки'!$L18:$O18)>2.5,(SUM('Баллы, оценки'!$L18:$O18)<3.5)),4,IF(AND(SUM('Баллы, оценки'!$L18:$O18)<=2.5,(SUM('Баллы, оценки'!$L18:$O18)>1.5)),3,2))) -> 2 | U4: =IF(SUM('Баллы, оценки'!$Q18:$T18)>=3.5,5,IF(AND(SUM('Баллы, оценки'!$Q18:$T18)>2.5,(SUM('Баллы, оценки'!$Q18:$T18)<3.5)),4,IF(AND(SUM('Баллы, оценки'!$Q18:$T18)<=2.5,(SUM('Баллы, оценки'!$Q18:$T18)>1.5)),3,2))) -> 2 | V4: 0.5 | AL4: =SUM('Баллы, оценки'!$B18:$E18,'Баллы, оценки'!$G18:$J18,'Баллы, оценки'!$L18:$O18,'Баллы, оценки'!$Q18:$T18,'Баллы, оценки'!$V18:$AF18,AH4:AK4) -> 7.5 | AM4: =32-COUNTA(B4:E4,G4:I4,L4:O4,Q4:T4,V4:AF4,AH4:AK4) -> 21 | AR4: 4 | AU4: =IF(AND('Баллы, оценки'!$AL18<=38,'Баллы, оценки'!$AL18>=31),5,IF(AND('Баллы, оценки'!$AL18<=30.9,'Баллы, оценки'!$AL18>=25),4,IF(AND('Баллы, оценки'!$AL18<=24.9,'Баллы, оценки'!$AL18>=21),3,н/а))) -> #NAME?
A5: Волков Григорий | B5: 0.5 | C5: 0.5 | D5: 0.5 | E5: 2.5 | F5: =IF(SUM('Баллы, оценки'!$B7:$E7)>=3.5,5,IF(AND(SUM('Баллы, оценки'!$B7:$E7)>2.5,(SUM('Баллы, оценки'!$B7:$E7)<3.5)),4,IF(AND(SUM('Баллы, оценки'!$B7:$E7)<=2.5,(SUM('Баллы, оценки'!$B7:$E7)>1.5)),3,2))) -> 5 | G5: 0.5 | H5: 0.5 | I5: 0.5 | J5: 2.5 | K5: =IF(SUM('Баллы, оценки'!$G7:$J7)>=3.5,5,IF(AND(SUM('Баллы, оценки'!$G7:$J7)>2.5,(SUM('Баллы, оценки'!$G7:$J7)<3.5)),4,IF(AND(SUM('Баллы, оценки'!$G7:$J7)<=2.5,(SUM('Баллы, оценки'!$G7:$J7)>1.5)),3,2))) -> 5 | L5: 0.5 | M5: 0.5 | N5: 0.5 | P5: =IF(SUM('Баллы, оценки'!$L7:$O7)>=3.5,5,IF(AND(SUM('Баллы, оценки'!$L7:$O7)>2.5,(SUM('Баллы, оценки'!$L7:$O7)<3.5)),4,IF(AND(SUM('Баллы, оценки'!$L7:$O7)<=2.5,(SUM('Баллы, оценки'!$L7:$O7)>1.5)),3,2))) -> 2 | U5: =IF(SUM('Баллы, оценки'!$Q7:$T7)>=3.5,5,IF(AND(SUM('Баллы, оценки'!$Q7:$T7)>2.5,(SUM('Баллы, оценки'!$Q7:$T7)<3.5)),4,IF(AND(SUM('Баллы, оценки'!$Q7:$T7)<=2.5,(SUM('Баллы, оценки'!$Q7:$T7)>1.5)),3,2))) -> 2 | V5: 0.5 | AL5: =SUM('Баллы, оценки'!$B7:$E7,'Баллы, оценки'!$G7:$J7,'Баллы, оценки'!$L7:$O7,'Баллы, оценки'!$Q7:$T7,'Баллы, оценки'!$V7:$AF7,AH5:AK5) -> 9.5 | AM5: =32-COUNTA(B5:E5,G5:I5,L5:O5,Q5:T5,V5:AF5,AH5:AK5) -> 21 | AR5: 4 | AU5: =IF(AND('Баллы, оценки'!$AL7<=38,'Баллы, оценки'!$AL7>=31),5,IF(AND('Баллы, оценки'!$AL7<=30.9,'Баллы, оценки'!$AL7>=25),4,IF(AND('Баллы, оценки'!$AL7<=24.9,'Баллы, оценки'!$AL7>=21),3,н/а))) -> #NAME?
A6: Зайцев Никита | B6: 0.5 | C6: 0.5 | D6: 0.5 | E6: 2.5 | F6: =IF(SUM('Баллы, оценки'!$B12:$E12)>=3.5,5,IF(AND(SUM('Баллы, оценки'!$B12:$E12)>2.5,(SUM('Баллы, оценки'!$B12:$E12)<3.5)),4,IF(AND(SUM('Баллы, оценки'!$B12:$E12)<=2.5,(SUM('Баллы, оценки'!$B12:$E12)>1.5)),3,2))) -> 5 | G6: 0.5 | H6: 0.5 | I6: 0.5 | J6: 2 | K6: =IF(SUM('Баллы, оценки'!$G12:$J12)>=3.5,5,IF(AND(SUM('Баллы, оценки'!$G12:$J12)>2.5,(SUM('Баллы, оценки'!$G12:$J12)<3.5)),4,IF(AND(SUM('Баллы, оценки'!$G12:$J12)<=2.5,(SUM('Баллы, оценки'!$G12:$J12)>1.5)),3,2))) -> 5 | L6: 0.5 | M6: 0.5 | N6: 0.5 | P6: =IF(SUM('Баллы, оценки'!$L12:$O12)>=3.5,5,IF(AND(SUM('Баллы, оценки'!$L12:$O12)>2.5,(SUM('Баллы, оценки'!$L12:$O12)<3.5)),4,IF(AND(SUM('Баллы, оценки'!$L12:$O12)<=2.5,(SUM('Баллы, оценки'!$L12:$O12)>1.5)),3,2))) -> 2 | U6: =IF(SUM('Баллы, оценки'!$Q12:$T12)>=3.5,5,IF(AND(SUM('Баллы, оценки'!$Q12:$T12)>2.5,(SUM('Баллы, оценки'!$Q12:$T12)<3.5)),4,IF(AND(SUM('Баллы, оценки'!$Q12:$T12)<=2.5,(SUM('Баллы, оценки'!$Q12:$T12)>1.5)),3,2))) -> 2 | V6: 0.5 | AL6: =SUM('Баллы, оценки'!$B12:$E12,'Баллы, оценки'!$G12:$J12,'Баллы, оценки'!$L12:$O12,'Баллы, оценки'!$Q12:$T12,'Баллы, оценки'!$V12:$AF12,AH6:AK6) -> 9 | AM6: =32-COUNTA(B6:E6,G6:I6,L6:O6,Q6:T6,V6:AF6,AH6:AK6) -> 21 | AR6: 4 | AU6: =IF(AND('Баллы, оценки'!$AL12<=38,'Баллы, оценки'!$AL12>=31),5,IF(AND('Баллы, оценки'!$AL12<=30.9,'Баллы, оценки'!$AL12>=25),4,IF(AND('Баллы, оценки'!$AL12<=24.9,'Баллы, оценки'!$AL12>=21),3,н/а))) -> #NAME?
A7: Свиков Илья | B7: 0.5 | C7: 0.5 | D7: 0.5 | E7: 2.5 | F7: =IF(SUM('Баллы, оценки'!$B26:$E26)>=3.5,5,IF(AND(SUM('Баллы, оценки'!$B26:$E26)>2.5,(SUM('Баллы, оценки'!$B26:$E26)<3.5)),4,IF(AND(SUM('Баллы, оценки'!$B26:$E26)<=2.5,(SUM('Баллы, оценки'!$B26:$E26)>1.5)),3,2))) -> 5 | G7: 0.5 | H7: 0.5 | I7: 0.5 | J7: 2 | K7: =IF(SUM('Баллы, оценки'!$G26:$J26)>=3.5,5,IF(AND(SUM('Баллы, оценки'!$G26:$J26)>2.5,(SUM('Баллы, оценки'!$G26:$J26)<3.5)),4,IF(AND(SUM('Баллы, оценки'!$G26:$J26)<=2.5,(SUM('Баллы, оценки'!$G26:$J26)>1.5)),3,2))) -> 2 | L7: 0.5 | M7: 0.5 | N7: 0.5 | P7: =IF(SUM('Баллы, оценки'!$L26:$O26)>=3.5,5,IF(AND(SUM('Баллы, оценки'!$L26:$O26)>2.5,(SUM('Баллы, оценки'!$L26:$O26)<3.5)),4,IF(AND(SUM('Баллы, оценки'!$L26:$O26)<=2.5,(SUM('Баллы, оценки'!$L26:$O26)>1.5)),3,2))) -> 2 | U7: =IF(SUM('Баллы, оценки'!$Q26:$T26)>=3.5,5,IF(AND(SUM('Баллы, оценки'!$Q26:$T26)>2.5,(SUM('Баллы, оценки'!$Q26:$T26)<3.5)),4,IF(AND(SUM('Баллы, оценки'!$Q26:$T26)<=2.5,(SUM('Баллы, оценки'!$Q26:$T26)>1.5)),3,2))) -> 2 | V7: 0.5 | AL7: =SUM('Баллы, оценки'!$B26:$E26,'Баллы, оценки'!$G26:$J26,'Баллы, оценки'!$L26:$O26,'Баллы, оценки'!$Q26:$T26,'Баллы, оценки'!$V26:$AF26,AH7:AK7) -> 5.5 | AM7: =32-COUNTA(B7:E7,G7:I7,L7:O7,Q7:T7,V7:AF7,AH7:AK7) -> 21 | AR7: 4 | AU7: =IF(AND('Баллы, оценки'!$AL26<=38,'Баллы, оценки'!$AL26>=31),5,IF(AND('Баллы, оценки'!$AL26<=30.9,'Баллы, оценки'!$AL26>=25),4,IF(AND('Баллы, оценки'!$AL26<=24.9,'Баллы, оценки'!$AL26>=21),3,н/а))) -> #NAME?
A8: Семёнов Никита | B8: 0.5 | C8: 0.5 | D8: 0.5 | E8: 2 | F8: =IF(SUM('Баллы, оценки'!$B27:$E27)>=3.5,5,IF(AND(SUM('Баллы, оценки'!$B27:$E27)>2.5,(SUM('Баллы, оценки'!$B27:$E27)<3.5)),4,IF(AND(SUM('Баллы, оценки'!$B27:$E27)<=2.5,(SUM('Баллы, оценки'!$B27:$E27)>1.5)),3,2))) -> 4 | G8: 0.5 | H8: 0.5 | I8: 0.5 | J8: 2.5 | K8: =IF(SUM('Баллы, оценки'!$G27:$J27)>=3.5,5,IF(AND(SUM('Баллы, оценки'!$G27:$J27)>2.5,(SUM('Баллы, оценки'!$G27:$J27)<3.5)),4,IF(AND(SUM('Баллы, оценки'!$G27:$J27)<=2.5,(SUM('Баллы, оценки'!$G27:$J27)>1.5)),3,2))) -> 2 | L8: 0.5 | M8: 0.5 | N8: 0.5 | P8: =IF(SUM('Баллы, оценки'!$L27:$O27)>=3.5,5,IF(AND(SUM('Баллы, оценки'!$L27:$O27)>2.5,(SUM('Баллы, оценки'!$L27:$O27)<3.5)),4,IF(AND(SUM('Баллы, оценки'!$L27:$O27)<=2.5,(SUM('Баллы, оценки'!$L27:$O27)>1.5)),3,2))) -> 2 | U8: =IF(SUM('Баллы, оценки'!$Q27:$T27)>=3.5,5,IF(AND(SUM('Баллы, оценки'!$Q27:$T27)>2.5,(SUM('Баллы, оценки'!$Q27:$T27)<3.5)),4,IF(AND(SUM('Баллы, оценки'!$Q27:$T27)<=2.5,(SUM('Баллы, оценки'!$Q27:$T27)>1.5)),3,2))) -> 2 | V8: 0.5 | AL8: =SUM('Баллы, оценки'!$B27:$E27,'Баллы, оценки'!$G27:$J27,'Баллы, оценки'!$L27:$O27,'Баллы, оценки'!$Q27:$T27,'Баллы, оценки'!$V27:$AF27,AH8:AK8) -> 5 | AM8: =32-COUNTA(B8:E8,G8:I8,L8:O8,Q8:T8,V8:AF8,AH8:AK8) -> 21 | AR8: 4 | AU8: =IF(AND('Баллы, оценки'!$AL27<=38,'Баллы, оценки'!$AL27>=31),5,IF(AND('Баллы, оценки'!$AL27<=30.9,'Баллы, оценки'!$AL27>=25),4,IF(AND('Баллы, оценки'!$AL27<=24.9,'Баллы, оценки'!$AL27>=21),3,н/а))) -> #NAME?
A9: Асмеев Никита | B9: 0.5 | C9: 0.5 | E9: 2 | F9: =IF(SUM('Баллы, оценки'!$B4:$E4)>=3.5,5,IF(AND(SUM('Баллы, оценки'!$B4:$E4)>2.5,(SUM('Баллы, оценки'!$B4:$E4)<3.5)),4,IF(AND(SUM('Баллы, оценки'!$B4:$E4)<=2.5,(SUM('Баллы, оценки'!$B4:$E4)>1.5)),3,2))) -> 5 | G9: 0.5 | H9: 0.5 | I9: 0.5 | J9: 2.5 | K9: =IF(SUM('Баллы, оценки'!$G4:$J4)>=3.5,5,IF(AND(SUM('Баллы, оценки'!$G4:$J4)>2.5,(SUM('Баллы, оценки'!$G4:$J4)<3.5)),4,IF(AND(SUM('Баллы, оценки'!$G4:$J4)<=2.5,(SUM('Баллы, оценки'!$G4:$J4)>1.5)),3,2))) -> 5 | L9: 0.5 | M9: 0.5 | N9: 0.5 | P9: =IF(SUM('Баллы, оценки'!$L4:$O4)>=3.5,5,IF(AND(SUM('Баллы, оценки'!$L4:$O4)>2.5,(SUM('Баллы, оценки'!$L4:$O4)<3.5)),4,IF(AND(SUM('Баллы, оценки'!$L4:$O4)<=2.5,(SUM('Баллы, оценки'!$L4:$O4)>1.5)),3,2))) -> 2 | U9: =IF(SUM('Баллы, оценки'!$Q4:$T4)>=3.5,5,IF(AND(SUM('Баллы, оценки'!$Q4:$T4)>2.5,(SUM('Баллы, оценки'!$Q4:$T4)<3.5)),4,IF(AND(SUM('Баллы, оценки'!$Q4:$T4)<=2.5,(SUM('Баллы, оценки'!$Q4:$T4)>1.5)),3,2))) -> 2 | V9: 0.5 | AL9: =SUM('Баллы, оценки'!$B4:$E4,'Баллы, оценки'!$G4:$J4,'Баллы, оценки'!$L4:$O4,'Баллы, оценки'!$Q4:$T4,'Баллы, оценки'!$V4:$AF4,AH9:AK9) -> 10.2 | AM9: =32-COUNTA(B9:E9,G9:I9,L9:O9,Q9:T9,V9:AF9,AH9:AK9) -> 22 | AR9: 4 | AU9: =IF(AND('Баллы, оценки'!$AL4<=38,'Баллы, оценки'!$AL4>=31),5,IF(AND('Баллы, оценки'!$AL4<=30.9,'Баллы, оценки'!$AL4>=25),4,IF(AND('Баллы, оценки'!$AL4<=24.9,'Баллы, оценки'!$AL4>=21),3,н/а))) -> #NAME?
A10: Ворожейкин Дмитрий | B10: 0.5 | C10: 0.5 | D10: 0.5 | E10: 2 | F10: =IF(SUM('Баллы, оценки'!$B8:$E8)>=3.5,5,IF(AND(SUM('Баллы, оценки'!$B8:$E8)>2.5,(SUM('Баллы, оценки'!$B8:$E8)<3.5)),4,IF(AND(SUM('Баллы, оценки'!$B8:$E8)<=2.5,(SUM('Баллы, оценки'!$B8:$E8)>1.5)),3,2))) -> 5 | G10: 0.5 | H10: 0.5 | I10: 0.5 | J10: 2 | K10: =IF(SUM('Баллы, оценки'!$G8:$J8)>=3.5,5,IF(AND(SUM('Баллы, оценки'!$G8:$J8)>2.5,(SUM('Баллы, оценки'!$G8:$J8)<3.5)),4,IF(AND(SUM('Баллы, оценки'!$G8:$J8)<=2.5,(SUM('Баллы, оценки'!$G8:$J8)>1.5)),3,2))) -> 5 | L10: 0.5 | M10: 0.5 | N10: 0.5 | P10: =IF(SUM('Баллы, оценки'!$L8:$O8)>=3.5,5,IF(AND(SUM('Баллы, оценки'!$L8:$O8)>2.5,(SUM('Баллы, оценки'!$L8:$O8)<3.5)),4,IF(AND(SUM('Баллы, оценки'!$L8:$O8)<=2.5,(SUM('Баллы, оценки'!$L8:$O8)>1.5)),3,2))) -> 2 | U10: =IF(SUM('Баллы, оценки'!$Q8:$T8)>=3.5,5,IF(AND(SUM('Баллы, оценки'!$Q8:$T8)>2.5,(SUM('Баллы, оценки'!$Q8:$T8)<3.5)),4,IF(AND(SUM('Баллы, оценки'!$Q8:$T8)<=2.5,(SUM('Баллы, оценки'!$Q8:$T8)>1.5)),3,2))) -> 2 | V10: 0.5 | AL10: =SUM('Баллы, оценки'!$B8:$E8,'Баллы, оценки'!$G8:$J8,'Баллы, оценки'!$L8:$O8,'Баллы, оценки'!$Q8:$T8,'Баллы, оценки'!$V8:$AF8,AH10:AK10) -> 9.5 | AM10: =32-COUNTA(B10:E10,G10:I10,L10:O10,Q10:T10,V10:AF10,AH10:AK10) -> 21 | AR10: 3 | AU10: =IF(AND('Баллы, оценки'!$AL8<=38,'Баллы, оценки'!$AL8>=31),5,IF(AND('Баллы, оценки'!$AL8<=30.9,'Баллы, оценки'!$AL8>=25),4,IF(AND('Баллы, оценки'!$AL8<=24.9,'Баллы, оценки'!$AL8>=21),3,н/а))) -> #NAME?
A11: Кузнецов Даниил | B11: 0.5 | C11: 0.5 | D11: 0.5 | E11: 2.5 | F11: =IF(SUM('Баллы, оценки'!$B16:$E16)>=3.5,5,IF(AND(SUM('Баллы, оценки'!$B16:$E16)>2.5,(SUM('Баллы, оценки'!$B16:$E16)<3.5)),4,IF(AND(SUM('Баллы, оценки'!$B16:$E16)<=2.5,(SUM('Баллы, оценки'!$B16:$E16)>1.5)),3,2))) -> 5 | G11: 0.5 | H11: 0.5 | I11: 0.5 | J11: 1.5 | K11: =IF(SUM('Баллы, оценки'!$G16:$J16)>=3.5,5,IF(AND(SUM('Баллы, оценки'!$G16:$J16)>2.5,(SUM('Баллы, оценки'!$G16:$J16)<3.5)),4,IF(AND(SUM('Баллы, оценки'!$G16:$J16)<=2.5,(SUM('Баллы, оценки'!$G16:$J16)>1.5)),3,2))) -> 3 | L11: 0.5 | M11: 0.5 | N11: 0.5 | P11: =IF(SUM('Баллы, оценки'!$L16:$O16)>=3.5,5,IF(AND(SUM('Баллы, оценки'!$L16:$O16)>2.5,(SUM('Баллы, оценки'!$L16:$O16)<3.5)),4,IF(AND(SUM('Баллы, оценки'!$L16:$O16)<=2.5,(SUM('Баллы, оценки'!$L16:$O16)>1.5)),3,2))) -> 2 | U11: =IF(SUM('Баллы, оценки'!$Q16:$T16)>=3.5,5,IF(AND(SUM('Баллы, оценки'!$Q16:$T16)>2.5,(SUM('Баллы, оценки'!$Q16:$T16)<3.5)),4,IF(AND(SUM('Баллы, оценки'!$Q16:$T16)<=2.5,(SUM('Баллы, оценки'!$Q16:$T16)>1.5)),3,2))) -> 2 | V11: 0.5 | AL11: =SUM('Баллы, оценки'!$B16:$E16,'Баллы, оценки'!$G16:$J16,'Баллы, оценки'!$L16:$O16,'Баллы, оценки'!$Q16:$T16,'Баллы, оценки'!$V16:$AF16,AH11:AK11) -> 8 | AM11: =32-COUNTA(B11:E11,G11:I11,L11:O11,Q11:T11,V11:AF11,AH11:AK11) -> 21 | AR11: 4 | AU11: =IF(AND('Баллы, оценки'!$AL16<=38,'Баллы, оценки'!$AL16>=31),5,IF(AND('Баллы, оценки'!$AL16<=30.9,'Баллы, оценки'!$AL16>=25),4,IF(AND('Баллы, оценки'!$AL16<=24.9,'Баллы, оценки'!$AL16>=21),3,н/а))) -> #NAME?
A12: Спирин Максим | B12: 0.5 | C12: 0.5 | E12: 2.5 | F12: =IF(SUM('Баллы, оценки'!$B28:$E28)>=3.5,5,IF(AND(SUM('Баллы, оценки'!$B28:$E28)>2.5,(SUM('Баллы, оценки'!$B28:$E28)<3.5)),4,IF(AND(SUM('Баллы, оценки'!$B28:$E28)<=2.5,(SUM('Баллы, оценки'!$B28:$E28)>1.5)),3,2))) -> 5 | G12: 0.5 | H12: 0.5 | I12: 0.5 | J12: 2 | K12: =IF(SUM('Баллы, оценки'!$G28:$J28)>=3.5,5,IF(AND(SUM('Баллы, оценки'!$G28:$J28)>2.5,(SUM('Баллы, оценки'!$G28:$J28)<3.5)),4,IF(AND(SUM('Баллы, оценки'!$G28:$J28)<=2.5,(SUM('Баллы, оценки'!$G28:$J28)>1.5)),3,2))) -> 2 | L12: 0.5 | M12: 0.5 | N12: 0.5 | P12: =IF(SUM('Баллы, оценки'!$L28:$O28)>=3.5,5,IF(AND(SUM('Баллы, оценки'!$L28:$O28)>2.5,(SUM('Баллы, оценки'!$L28:$O28)<3.5)),4,IF(AND(SUM('Баллы, оценки'!$L28:$O28)<=2.5,(SUM('Баллы, оценки'!$L28:$O28)>1.5)),3,2))) -> 2 | U12: =IF(SUM('Баллы, оценки'!$Q28:$T28)>=3.5,5,IF(AND(SUM('Баллы, оценки'!$Q28:$T28)>2.5,(SUM('Баллы, оценки'!$Q28:$T28)<3.5)),4,IF(AND(SUM('Баллы, оценки'!$Q28:$T28)<=2.5,(SUM('Баллы, оценки'!$Q28:$T28)>1.5)),3,2))) -> 2 | V12: 0.5 | AL12: =SUM('Баллы, оценки'!$B28:$E28,'Баллы, оценки'!$G28:$J28,'Баллы, оценки'!$L28:$O28,'Баллы, оценки'!$Q28:$T28,'Баллы, оценки'!$V28:$AF28,AH12:AK12) -> 5 | AM12: =32-COUNTA(B12:E12,G12:I12,L12:O12,Q12:T12,V12:AF12,AH12:AK12) -> 22 | AR12: 4 | AU12: =IF(AND('Баллы, оценки'!$AL28<=38,'Баллы, оценки'!$AL28>=31),5,IF(AND('Баллы, оценки'!$AL28<=30.9,'Баллы, оценки'!$AL28>=25),4,IF(AND('Баллы, оценки'!$AL28<=24.9,'Баллы, оценки'!$AL28>=21),3,н/а))) -> #NAME?
A13: Живодсков Данила | C13: 0.5 | D13: 0.5 | E13: 2.5 | F13: =IF(SUM('Баллы, оценки'!$B10:$E10)>=3.5,5,IF(AND(SUM('Баллы, оценки'!$B10:$E10)>2.5,(SUM('Баллы, оценки'!$B10:$E10)<3.5)),4,IF(AND(SUM('Баллы, оценки'!$B10:$E10)<=2.5,(SUM('Баллы, оценки'!$B10:$E10)>1.5)),3,2))) -> 5 | G13: 0.5 | H13: 0.5 | I13: 0.5 | J13: 1.5 | K13: =IF(SUM('Баллы, оценки'!$G10:$J10)>=3.5,5,IF(AND(SUM('Баллы, оценки'!$G10:$J10)>2.5,(SUM('Баллы, оценки'!$G10:$J10)<3.5)),4,IF(AND(SUM('Баллы, оценки'!$G10:$J10)<=2.5,(SUM('Баллы, оценки'!$G10:$J10)>1.5)),3,2))) -> 5 | L13: 0.5 | M13: 0.5 | N13: 0.5 | P13: =IF(SUM('Баллы, оценки'!$L10:$O10)>=3.5,5,IF(AND(SUM('Баллы, оценки'!$L10:$O10)>2.5,(SUM('Баллы, оценки'!$L10:$O10)<3.5)),4,IF(AND(SUM('Баллы, оценки'!$L10:$O10)<=2.5,(SUM('Баллы, оценки'!$L10:$O10)>1.5)),3,2))) -> 2 | U13: =IF(SUM('Баллы, оценки'!$Q10:$T10)>=3.5,5,IF(AND(SUM('Баллы, оценки'!$Q10:$T10)>2.5,(SUM('Баллы, оценки'!$Q10:$T10)<3.5)),4,IF(AND(SUM('Баллы, оценки'!$Q10:$T10)<=2.5,(SUM('Баллы, оценки'!$Q10:$T10)>1.5)),3,2))) -> 2 | V13: 0.5 | AL13: =SUM('Баллы, оценки'!$B10:$E10,'Баллы, оценки'!$G10:$J10,'Баллы, оценки'!$L10:$O10,'Баллы, оценки'!$Q10:$T10,'Баллы, оценки'!$V10:$AF10,AH13:AK13) -> 9 | AM13: =32-COUNTA(B13:E13,G13:I13,L13:O13,Q13:T13,V13:AF13,AH13:AK13) -> 22 | AR13: 5- | AU13: =IF(AND('Баллы, оценки'!$AL10<=38,'Баллы, оценки'!$AL10>=31),5,IF(AND('Баллы, оценки'!$AL10<=30.9,'Баллы, оценки'!$AL10>=25),4,IF(AND('Баллы, оценки'!$AL10<=24.9,'Баллы, оценки'!$AL10>=21),3,н/а))) -> #NAME?
A14: Антонов Юрий | B14: 0.5 | C14: 0.5 | D14: 0.5 | E14: 2.5 | F14: =IF(SUM('Баллы, оценки'!$B3:$E3)>=3.5,5,IF(AND(SUM('Баллы, оценки'!$B3:$E3)>2.5,(SUM('Баллы, оценки'!$B3:$E3)<3.5)),4,IF(AND(SUM('Баллы, оценки'!$B3:$E3)<=2.5,(SUM('Баллы, оценки'!$B3:$E3)>1.5)),3,2))) -> 5 | G14: 0.5 | H14: 0.5 | I14: 0.5 | J14: 1 | K14: =IF(SUM('Баллы, оценки'!$G3:$J3)>=3.5,5,IF(AND(SUM('Баллы, оценки'!$G3:$J3)>2.5,(SUM('Баллы, оценки'!$G3:$J3)<3.5)),4,IF(AND(SUM('Баллы, оценки'!$G3:$J3)<=2.5,(SUM('Баллы, оценки'!$G3:$J3)>1.5)),3,2))) -> 5 | L14: 0.5 | M14: 0.5 | N14: 0.5 | P14: =IF(SUM('Баллы, оценки'!$L3:$O3)>=3.5,5,IF(AND(SUM('Баллы, оценки'!$L3:$O3)>2.5,(SUM('Баллы, оценки'!$L3:$O3)<3.5)),4,IF(AND(SUM('Баллы, оценки'!$L3:$O3)<=2.5,(SUM('Баллы, оценки'!$L3:$O3)>1.5)),3,2))) -> 2 | U14: =IF(SUM('Баллы, оценки'!$Q3:$T3)>=3.5,5,IF(AND(SUM('Баллы, оценки'!$Q3:$T3)>2.5,(SUM('Баллы, оценки'!$Q3:$T3)<3.5)),4,IF(AND(SUM('Баллы, оценки'!$Q3:$T3)<=2.5,(SUM('Баллы, оценки'!$Q3:$T3)>1.5)),3,2))) -> 2 | AL14: =SUM('Баллы, оценки'!$B3:$E3,'Баллы, оценки'!$G3:$J3,'Баллы, оценки'!$L3:$O3,'Баллы, оценки'!$Q3:$T3,'Баллы, оценки'!$V3:$AF3,AH14:AK14) -> 10.3 | AM14: =32-COUNTA(B14:E14,G14:I14,L14:O14,Q14:T14,V14:AF14,AH14:AK14) -> 22 | AR14: 4 | AU14: =IF(AND('Баллы, оценки'!$AL3<=38,'Баллы, оценки'!$AL3>=31),5,IF(AND('Баллы, оценки'!$AL3<=30.9,'Баллы, оценки'!$AL3>=25),4,IF(AND('Баллы, оценки'!$AL3<=24.9,'Баллы, оценки'!$AL3>=21),3,н/а))) -> #NAME?
A15: Иванова Яна | B15: 0.5 | C15: 0.5 | D15: 0.5 | E15: 2.5 | F15: =IF(SUM('Баллы, оценки'!$B13:$E13)>=3.5,5,IF(AND(SUM('Баллы, оценки'!$B13:$E13)>2.5,(SUM('Баллы, оценки'!$B13:$E13)<3.5)),4,IF(AND(SUM('Баллы, оценки'!$B13:$E13)<=2.5,(SUM('Баллы, оценки'!$B13:$E13)>1.5)),3,2))) -> 5 | G15: 0.5 | H15: 0.5 | I15: 0.5 | J15: 0.5 | K15: =IF(SUM('Баллы, оценки'!$G13:$J13)>=3.5,5,IF(AND(SUM('Баллы, оценки'!$G13:$J13)>2.5,(SUM('Баллы, оценки'!$G13:$J13)<3.5)),4,IF(AND(SUM('Баллы, оценки'!$G13:$J13)<=2.5,(SUM('Баллы, оценки'!$G13:$J13)>1.5)),3,2))) -> 4 | L15: 0.5 | M15: 0.5 | N15: 0.5 | P15: =IF(SUM('Баллы, оценки'!$L13:$O13)>=3.5,5,IF(AND(SUM('Баллы, оценки'!$L13:$O13)>2.5,(SUM('Баллы, оценки'!$L13:$O13)<3.5)),4,IF(AND(SUM('Баллы, оценки'!$L13:$O13)<=2.5,(SUM('Баллы, оценки'!$L13:$O13)>1.5)),3,2))) -> 2 | U15: =IF(SUM('Баллы, оценки'!$Q13:$T13)>=3.5,5,IF(AND(SUM('Баллы, оценки'!$Q13:$T13)>2.5,(SUM('Баллы, оценки'!$Q13:$T13)<3.5)),4,IF(AND(SUM('Баллы, оценки'!$Q13:$T13)<=2.5,(SUM('Баллы, оценки'!$Q13:$T13)>1.5)),3,2))) -> 2 | V15: 0.5 | AL15: =SUM('Баллы, оценки'!$B13:$E13,'Баллы, оценки'!$G13:$J13,'Баллы, оценки'!$L13:$O13,'Баллы, оценки'!$Q13:$T13,'Баллы, оценки'!$V13:$AF13,AH15:AK15) -> 8.5 | AM15: =32-COUNTA(B15:E15,G15:I15,L15:O15,Q15:T15,V15:AF15,AH15:AK15) -> 21 | AR15: 4 | AU15: =IF(AND('Баллы, оценки'!$AL13<=38,'Баллы, оценки'!$AL13>=31),5,IF(AND('Баллы, оценки'!$AL13<=30.9,'Баллы, оценки'!$AL13>=25),4,IF(AND('Баллы, оценки'!$AL13<=24.9,'Баллы, оценки'!$AL13>=21),3,н/а))) -> #NAME?
A16: Краснянский Евгений | B16: 0.5 | C16: 0.5 | D16: 0.5 | E16: 2.5 | F16: =IF(SUM('Баллы, оценки'!$B15:$E15)>=3.5,5,IF(AND(SUM('Баллы, оценки'!$B15:$E15)>2.5,(SUM('Баллы, оценки'!$B15:$E15)<3.5)),4,IF(AND(SUM('Баллы, оценки'!$B15:$E15)<=2.5,(SUM('Баллы, оценки'!$B15:$E15)>1.5)),3,2))) -> 5 | G16: 0.5 | H16: 0.5 | I16: 0.5 | J16: 0.5 | K16: =IF(SUM('Баллы, оценки'!$G15:$J15)>=3.5,5,IF(AND(SUM('Баллы, оценки'!$G15:$J15)>2.5,(SUM('Баллы, оценки'!$G15:$J15)<3.5)),4,IF(AND(SUM('Баллы, оценки'!$G15:$J15)<=2.5,(SUM('Баллы, оценки'!$G15:$J15)>1.5)),3,2))) -> 3 | L16: 0.5 | M16: 0.5 | N16: 0.5 | P16: =IF(SUM('Баллы, оценки'!$L15:$O15)>=3.5,5,IF(AND(SUM('Баллы, оценки'!$L15:$O15)>2.5,(SUM('Баллы, оценки'!$L15:$O15)<3.5)),4,IF(AND(SUM('Баллы, оценки'!$L15:$O15)<=2.5,(SUM('Баллы, оценки'!$L15:$O15)>1.5)),3,2))) -> 2 | U16: =IF(SUM('Баллы, оценки'!$Q15:$T15)>=3.5,5,IF(AND(SUM('Баллы, оценки'!$Q15:$T15)>2.5,(SUM('Баллы, оценки'!$Q15:$T15)<3.5)),4,IF(AND(SUM('Баллы, оценки'!$Q15:$T15)<=2.5,(SUM('Баллы, оценки'!$Q15:$T15)>1.5)),3,2))) -> 2 | V16: 0.5 | AL16: =SUM('Баллы, оценки'!$B15:$E15,'Баллы, оценки'!$G15:$J15,'Баллы, оценки'!$L15:$O15,'Баллы, оценки'!$Q15:$T15,'Баллы, оценки'!$V15:$AF15,AH16:AK16) -> 8 | AM16: =32-COUNTA(B16:E16,G16:I16,L16:O16,Q16:T16,V16:AF16,AH16:AK16) -> 21 | AR16: 4 | AU16: =IF(AND('Баллы, оценки'!$AL15<=38,'Баллы, оценки'!$AL15>=31),5,IF(AND('Баллы, оценки'!$AL15<=30.9,'Баллы, оценки'!$AL15>=25),4,IF(AND('Баллы, оценки'!$AL15<=24.9,'Баллы, оценки'!$AL15>=21),3,н/а))) -> #NAME?
A17: Рысев Максим | B17: 0.5 | C17: 0.5 | D17: 0.5 | E17: 2 | F17: =IF(SUM('Баллы, оценки'!$B25:$E25)>=3.5,5,IF(AND(SUM('Баллы, оценки'!$B25:$E25)>2.5,(SUM('Баллы, оценки'!$B25:$E25)<3.5)),4,IF(AND(SUM('Баллы, оценки'!$B25:$E25)<=2.5,(SUM('Баллы, оценки'!$B25:$E25)>1.5)),3,2))) -> 5 | G17: 0.5 | H17: 0.5 | I17: 0.5 | J17: 1 | K17: =IF(SUM('Баллы, оценки'!$G25:$J25)>=3.5,5,IF(AND(SUM('Баллы, оценки'!$G25:$J25)>2.5,(SUM('Баллы, оценки'!$G25:$J25)<3.5)),4,IF(AND(SUM('Баллы, оценки'!$G25:$J25)<=2.5,(SUM('Баллы, оценки'!$G25:$J25)>1.5)),3,2))) -> 2 | L17: 0.5 | M17: 0.5 | N17: 0.5 | P17: =IF(SUM('Баллы, оценки'!$L25:$O25)>=3.5,5,IF(AND(SUM('Баллы, оценки'!$L25:$O25)>2.5,(SUM('Баллы, оценки'!$L25:$O25)<3.5)),4,IF(AND(SUM('Баллы, оценки'!$L25:$O25)<=2.5,(SUM('Баллы, оценки'!$L25:$O25)>1.5)),3,2))) -> 2 | U17: =IF(SUM('Баллы, оценки'!$Q25:$T25)>=3.5,5,IF(AND(SUM('Баллы, оценки'!$Q25:$T25)>2.5,(SUM('Баллы, оценки'!$Q25:$T25)<3.5)),4,IF(AND(SUM('Баллы, оценки'!$Q25:$T25)<=2.5,(SUM('Баллы, оценки'!$Q25:$T25)>1.5)),3,2))) -> 2 | V17: 0.5 | AL17: =SUM('Баллы, оценки'!$B25:$E25,'Баллы, оценки'!$G25:$J25,'Баллы, оценки'!$L25:$O25,'Баллы, оценки'!$Q25:$T25,'Баллы, оценки'!$V25:$AF25,AH17:AK17) -> 6 | AM17: =32-COUNTA(B17:E17,G17:I17,L17:O17,Q17:T17,V17:AF17,AH17:AK17) -> 21 | AR17: 4 | AU17: =IF(AND('Баллы, оценки'!$AL25<=38,'Баллы, оценки'!$AL25>=31),5,IF(AND('Баллы, оценки'!$AL25<=30.9,'Баллы, оценки'!$AL25>=25),4,IF(AND('Баллы, оценки'!$AL25<=24.9,'Баллы, оценки'!$AL25>=21),3,н/а))) -> #NAME?
A18: Беляева Екатерина | B18: 0.5 | C18: 0.5 | D18: 0.5 | E18: 2 | F18: =IF(SUM('Баллы, оценки'!$B5:$E5)>=3.5,5,IF(AND(SUM('Баллы, оценки'!$B5:$E5)>2.5,(SUM('Баллы, оценки'!$B5:$E5)<3.5)),4,IF(AND(SUM('Баллы, оценки'!$B5:$E5)<=2.5,(SUM('Баллы, оценки'!$B5:$E5)>1.5)),3,2))) -> 5 | G18: 0.5 | H18: 0.5 | I18: 0.5 | J18: 0.5 | K18: =IF(SUM('Баллы, оценки'!$G5:$J5)>=3.5,5,IF(AND(SUM('Баллы, оценки'!$G5:$J5)>2.5,(SUM('Баллы, оценки'!$G5:$J5)<3.5)),4,IF(AND(SUM('Баллы, оценки'!$G5:$J5)<=2.5,(SUM('Баллы, оценки'!$G5:$J5)>1.5)),3,2))) -> 5 | L18: 0.5 | M18: 0.5 | N18: 0.5 | P18: =IF(SUM('Баллы, оценки'!$L5:$O5)>=3.5,5,IF(AND(SUM('Баллы, оценки'!$L5:$O5)>2.5,(SUM('Баллы, оценки'!$L5:$O5)<3.5)),4,IF(AND(SUM('Баллы, оценки'!$L5:$O5)<=2.5,(SUM('Баллы, оценки'!$L5:$O5)>1.5)),3,2))) -> 2 | U18: =IF(SUM('Баллы, оценки'!$Q5:$T5)>=3.5,5,IF(AND(SUM('Баллы, оценки'!$Q5:$T5)>2.5,(SUM('Баллы, оценки'!$Q5:$T5)<3.5)),4,IF(AND(SUM('Баллы, оценки'!$Q5:$T5)<=2.5,(SUM('Баллы, оценки'!$Q5:$T5)>1.5)),3,2))) -> 2 | V18: 0.5 | AL18: =SUM('Баллы, оценки'!$B5:$E5,'Баллы, оценки'!$G5:$J5,'Баллы, оценки'!$L5:$O5,'Баллы, оценки'!$Q5:$T5,'Баллы, оценки'!$V5:$AF5,AH18:AK18) -> 10 | AM18: =32-COUNTA(B18:E18,G18:I18,L18:O18,Q18:T18,V18:AF18,AH18:AK18) -> 21 | AR18: 4 | AU18: =IF(AND('Баллы, оценки'!$AL5<=38,'Баллы, оценки'!$AL5>=31),5,IF(AND('Баллы, оценки'!$AL5<=30.9,'Баллы, оценки'!$AL5>=25),4,IF(AND('Баллы, оценки'!$AL5<=24.9,'Баллы, оценки'!$AL5>=21),3,н/а))) -> #NAME?
A19: Конкин Илья | B19: 0.5 | C19: 0.5 | D19: 0.5 | E19: 0.5 | F19: =IF(SUM('Баллы, оценки'!$B14:$E14)>=3.5,5,IF(AND(SUM('Баллы, оценки'!$B14:$E14)>2.5,(SUM('Баллы, оценки'!$B14:$E14)<3.5)),4,IF(AND(SUM('Баллы, оценки'!$B14:$E14)<=2.5,(SUM('Баллы, оценки'!$B14:$E14)>1.5)),3,2))) -> 5 | G19: 0.5 | H19: 0.5 | I19: 0.5 | J19: 2 | K19: =IF(SUM('Баллы, оценки'!$G14:$J14)>=3.5,5,IF(AND(SUM('Баллы, оценки'!$G14:$J14)>2.5,(SUM('Баллы, оценки'!$G14:$J14)<3.5)),4,IF(AND(SUM('Баллы, оценки'!$G14:$J14)<=2.5,(SUM('Баллы, оценки'!$G14:$J14)>1.5)),3,2))) -> 3 | L19: 0.5 | M19: 0.5 | N19: 0.5 | P19: =IF(SUM('Баллы, оценки'!$L14:$O14)>=3.5,5,IF(AND(SUM('Баллы, оценки'!$L14:$O14)>2.5,(SUM('Баллы, оценки'!$L14:$O14)<3.5)),4,IF(AND(SUM('Баллы, оценки'!$L14:$O14)<=2.5,(SUM('Баллы, оценки'!$L14:$O14)>1.5)),3,2))) -> 2 | U19: =IF(SUM('Баллы, оценки'!$Q14:$T14)>=3.5,5,IF(AND(SUM('Баллы, оценки'!$Q14:$T14)>2.5,(SUM('Баллы, оценки'!$Q14:$T14)<3.5)),4,IF(AND(SUM('Баллы, оценки'!$Q14:$T14)<=2.5,(SUM('Баллы, оценки'!$Q14:$T14)>1.5)),3,2))) -> 2 | V19: 0.5 | AL19: =SUM('Баллы, оценки'!$B14:$E14,'Баллы, оценки'!$G14:$J14,'Баллы, оценки'!$L14:$O14,'Баллы, оценки'!$Q14:$T14,'Баллы, оценки'!$V14:$AF14,AH19:AK19) -> 8 | AM19: =32-COUNTA(B19:E19,G19:I19,L19:O19,Q19:T19,V19:AF19,AH19:AK19) -> 21 | AR19: 4 | AU19: =IF(AND('Баллы, оценки'!$AL14<=38,'Баллы, оценки'!$AL14>=31),5,IF(AND('Баллы, оценки'!$AL14<=30.9,'Баллы, оценки'!$AL14>=25),4,IF(AND('Баллы, оценки'!$AL14<=24.9,'Баллы, оценки'!$AL14>=21),3,н/а))) -> #NAME?
A20: Журин Степан | C20: 0.5 | E20: 0.5 | F20: =IF(SUM('Баллы, оценки'!$B11:$E11)>=3.5,5,IF(AND(SUM('Баллы, оценки'!$B11:$E11)>2.5,(SUM('Баллы, оценки'!$B11:$E11)<3.5)),4,IF(AND(SUM('Баллы, оценки'!$B11:$E11)<=2.5,(SUM('Баллы, оценки'!$B11:$E11)>1.5)),3,2))) -> 5 | G20: 0.5 | H20: 0.5 | I20: 0.5 | J20: 2.5 | K20: =IF(SUM('Баллы, оценки'!$G11:$J11)>=3.5,5,IF(AND(SUM('Баллы, оценки'!$G11:$J11)>2.5,(SUM('Баллы, оценки'!$G11:$J11)<3.5)),4,IF(AND(SUM('Баллы, оценки'!$G11:$J11)<=2.5,(SUM('Баллы, оценки'!$G11:$J11)>1.5)),3,2))) -> 4 | L20: 0.5 | M20: 0.5 | N20: 0.5 | P20: =IF(SUM('Баллы, оценки'!$L11:$O11)>=3.5,5,IF(AND(SUM('Баллы, оценки'!$L11:$O11)>2.5,(SUM('Баллы, оценки'!$L11:$O11)<3.5)),4,IF(AND(SUM('Баллы, оценки'!$L11:$O11)<=2.5,(SUM('Баллы, оценки'!$L11:$O11)>1.5)),3,2))) -> 2 | U20: =IF(SUM('Баллы, оценки'!$Q11:$T11)>=3.5,5,IF(AND(SUM('Баллы, оценки'!$Q11:$T11)>2.5,(SUM('Баллы, оценки'!$Q11:$T11)<3.5)),4,IF(AND(SUM('Баллы, оценки'!$Q11:$T11)<=2.5,(SUM('Баллы, оценки'!$Q11:$T11)>1.5)),3,2))) -> 2 | V20: 0.5 | AL20: =SUM('Баллы, оценки'!$B11:$E11,'Баллы, оценки'!$G11:$J11,'Баллы, оценки'!$L11:$O11,'Баллы, оценки'!$Q11:$T11,'Баллы, оценки'!$V11:$AF11,AH20:AK20) -> 9 | AM20: =32-COUNTA(B20:E20,G20:I20,L20:O20,Q20:T20,V20:AF20,AH20:AK20) -> 23 | AU20: =IF(AND('Баллы, оценки'!$AL11<=38,'Баллы, оценки'!$AL11>=31),5,IF(AND('Баллы, оценки'!$AL11<=30.9,'Баллы, оценки'!$AL11>=25),4,IF(AND('Баллы, оценки'!$AL11<=24.9,'Баллы, оценки'!$AL11>=21),3,н/а))) -> #NAME?
A21: Панфилов Андрей | B21: 0.5 | C21: 0.5 | D21: 0.5 | E21: 2.5 | F21: =IF(SUM('Баллы, оценки'!$B21:$E21)>=3.5,5,IF(AND(SUM('Баллы, оценки'!$B21:$E21)>2.5,(SUM('Баллы, оценки'!$B21:$E21)<3.5)),4,IF(AND(SUM('Баллы, оценки'!$B21:$E21)<=2.5,(SUM('Баллы, оценки'!$B21:$E21)>1.5)),3,2))) -> 5 | J21: 2 | K21: =IF(SUM('Баллы, оценки'!$G21:$J21)>=3.5,5,IF(AND(SUM('Баллы, оценки'!$G21:$J21)>2.5,(SUM('Баллы, оценки'!$G21:$J21)<3.5)),4,IF(AND(SUM('Баллы, оценки'!$G21:$J21)<=2.5,(SUM('Баллы, оценки'!$G21:$J21)>1.5)),3,2))) -> 3 | N21: 0.5 | P21: =IF(SUM('Баллы, оценки'!$L21:$O21)>=3.5,5,IF(AND(SUM('Баллы, оценки'!$L21:$O21)>2.5,(SUM('Баллы, оценки'!$L21:$O21)<3.5)),4,IF(AND(SUM('Баллы, оценки'!$L21:$O21)<=2.5,(SUM('Баллы, оценки'!$L21:$O21)>1.5)),3,2))) -> 2 | U21: =IF(SUM('Баллы, оценки'!$Q21:$T21)>=3.5,5,IF(AND(SUM('Баллы, оценки'!$Q21:$T21)>2.5,(SUM('Баллы, оценки'!$Q21:$T21)<3.5)),4,IF(AND(SUM('Баллы, оценки'!$Q21:$T21)<=2.5,(SUM('Баллы, оценки'!$Q21:$T21)>1.5)),3,2))) -> 2 | V21: 0.5 | AL21: =SUM('Баллы, оценки'!$B21:$E21,'Баллы, оценки'!$G21:$J21,'Баллы, оценки'!$L21:$O21,'Баллы, оценки'!$Q21:$T21,'Баллы, оценки'!$V21:$AF21,AH21:AK21) -> 7 | AM21: =32-COUNTA(B21:E21,G21:I21,L21:O21,Q21:T21,V21:AF21,AH21:AK21) -> 26 | AR21: 4 | AU21: =IF(AND('Баллы, оценки'!$AL21<=38,'Баллы, оценки'!$AL21>=31),5,IF(AND('Баллы, оценки'!$AL21<=30.9,'Баллы, оценки'!$AL21>=25),4,IF(AND('Баллы, оценки'!$AL21<=24.9,'Баллы, оценки'!$AL21>=21),3,н/а))) -> #NAME?
A22: Дурандин Александр | B22: 0.5 | C22: 0.5 | E22: 2 | F22: =IF(SUM('Баллы, оценки'!$B9:$E9)>=3.5,5,IF(AND(SUM('Баллы, оценки'!$B9:$E9)>2.5,(SUM('Баллы, оценки'!$B9:$E9)<3.5)),4,IF(AND(SUM('Баллы, оценки'!$B9:$E9)<=2.5,(SUM('Баллы, оценки'!$B9:$E9)>1.5)),3,2))) -> 4 | G22: 0.5 | J22: 1.5 | K22: =IF(SUM('Баллы, оценки'!$G9:$J9)>=3.5,5,IF(AND(SUM('Баллы, оценки'!$G9:$J9)>2.5,(SUM('Баллы, оценки'!$G9:$J9)<3.5)),4,IF(AND(SUM('Баллы, оценки'!$G9:$J9)<=2.5,(SUM('Баллы, оценки'!$G9:$J9)>1.5)),3,2))) -> 5 | L22: 0.5 | M22: 0.5 | N22: 0.5 | P22: =IF(SUM('Баллы, оценки'!$L9:$O9)>=3.5,5,IF(AND(SUM('Баллы, оценки'!$L9:$O9)>2.5,(SUM('Баллы, оценки'!$L9:$O9)<3.5)),4,IF(AND(SUM('Баллы, оценки'!$L9:$O9)<=2.5,(SUM('Баллы, оценки'!$L9:$O9)>1.5)),3,2))) -> 2 | U22: =IF(SUM('Баллы, оценки'!$Q9:$T9)>=3.5,5,IF(AND(SUM('Баллы, оценки'!$Q9:$T9)>2.5,(SUM('Баллы, оценки'!$Q9:$T9)<3.5)),4,IF(AND(SUM('Баллы, оценки'!$Q9:$T9)<=2.5,(SUM('Баллы, оценки'!$Q9:$T9)>1.5)),3,2))) -> 2 | AL22: =SUM('Баллы, оценки'!$B9:$E9,'Баллы, оценки'!$G9:$J9,'Баллы, оценки'!$L9:$O9,'Баллы, оценки'!$Q9:$T9,'Баллы, оценки'!$V9:$AF9,AH22:AK22) -> 9 | AM22: =32-COUNTA(B22:E22,G22:I22,L22:O22,Q22:T22,V22:AF22,AH22:AK22) -> 25 | AR22: 3 | AU22: =IF(AND('Баллы, оценки'!$AL9<=38,'Баллы, оценки'!$AL9>=31),5,IF(AND('Баллы, оценки'!$AL9<=30.9,'Баллы, оценки'!$AL9>=25),4,IF(AND('Баллы, оценки'!$AL9<=24.9,'Баллы, оценки'!$AL9>=21),3,н/а))) -> #NAME?
A23: Машинистов Никита | B23: 0.5 | C23: 0.5 | F23: =IF(SUM('Баллы, оценки'!$B20:$E20)>=3.5,5,IF(AND(SUM('Баллы, оценки'!$B20:$E20)>2.5,(SUM('Баллы, оценки'!$B20:$E20)<3.5)),4,IF(AND(SUM('Баллы, оценки'!$B20:$E20)<=2.5,(SUM('Баллы, оценки'!$B20:$E20)>1.5)),3,2))) -> 2 | G23: 0.5 | H23: 0.5 | I23: 0.5 | J23: 2 | K23: =IF(SUM('Баллы, оценки'!$G20:$J20)>=3.5,5,IF(AND(SUM('Баллы, оценки'!$G20:$J20)>2.5,(SUM('Баллы, оценки'!$G20:$J20)<3.5)),4,IF(AND(SUM('Баллы, оценки'!$G20:$J20)<=2.5,(SUM('Баллы, оценки'!$G20:$J20)>1.5)),3,2))) -> 5 | L23: 0.5 | M23: 0.5 | N23: 0.5 | P23: =IF(SUM('Баллы, оценки'!$L20:$O20)>=3.5,5,IF(AND(SUM('Баллы, оценки'!$L20:$O20)>2.5,(SUM('Баллы, оценки'!$L20:$O20)<3.5)),4,IF(AND(SUM('Баллы, оценки'!$L20:$O20)<=2.5,(SUM('Баллы, оценки'!$L20:$O20)>1.5)),3,2))) -> 2 | U23: =IF(SUM('Баллы, оценки'!$Q20:$T20)>=3.5,5,IF(AND(SUM('Баллы, оценки'!$Q20:$T20)>2.5,(SUM('Баллы, оценки'!$Q20:$T20)<3.5)),4,IF(AND(SUM('Баллы, оценки'!$Q20:$T20)<=2.5,(SUM('Баллы, оценки'!$Q20:$T20)>1.5)),3,2))) -> 2 | V23: 0.5 | AL23: =SUM('Баллы, оценки'!$B20:$E20,'Баллы, оценки'!$G20:$J20,'Баллы, оценки'!$L20:$O20,'Баллы, оценки'!$Q20:$T20,'Баллы, оценки'!$V20:$AF20,AH23:AK23) -> 7 | AM23: =32-COUNTA(B23:E23,G23:I23,L23:O23,Q23:T23,V23:AF23,AH23:AK23) -> 23 | AR23: 4 | AU23: =IF(AND('Баллы, оценки'!$AL20<=38,'Баллы, оценки'!$AL20>=31),5,IF(AND('Баллы, оценки'!$AL20<=30.9,'Баллы, оценки'!$AL20>=25),4,IF(AND('Баллы, оценки'!$AL20<=24.9,'Баллы, оценки'!$AL20>=21),3,н/а))) -> #NAME?
A24: Ракитин Олег | B24: 0.5 | C24: 0.5 | D24: 0.5 | F24: =IF(SUM('Баллы, оценки'!$B23:$E23)>=3.5,5,IF(AND(SUM('Баллы, оценки'!$B23:$E23)>2.5,(SUM('Баллы, оценки'!$B23:$E23)<3.5)),4,IF(AND(SUM('Баллы, оценки'!$B23:$E23)<=2.5,(SUM('Баллы, оценки'!$B23:$E23)>1.5)),3,2))) -> 2 | G24: 0.5 | H24: 0.5 | I24: 0.5 | J24: 1.5 | K24: =IF(SUM('Баллы, оценки'!$G23:$J23)>=3.5,5,IF(AND(SUM('Баллы, оценки'!$G23:$J23)>2.5,(SUM('Баллы, оценки'!$G23:$J23)<3.5)),4,IF(AND(SUM('Баллы, оценки'!$G23:$J23)<=2.5,(SUM('Баллы, оценки'!$G23:$J23)>1.5)),3,2))) -> 5 | L24: 0.5 | M24: 0.5 | N24: 0.5 | P24: =IF(SUM('Баллы, оценки'!$L23:$O23)>=3.5,5,IF(AND(SUM('Баллы, оценки'!$L23:$O23)>2.5,(SUM('Баллы, оценки'!$L23:$O23)<3.5)),4,IF(AND(SUM('Баллы, оценки'!$L23:$O23)<=2.5,(SUM('Баллы, оценки'!$L23:$O23)>1.5)),3,2))) -> 2 | U24: =IF(SUM('Баллы, оценки'!$Q23:$T23)>=3.5,5,IF(AND(SUM('Баллы, оценки'!$Q23:$T23)>2.5,(SUM('Баллы, оценки'!$Q23:$T23)<3.5)),4,IF(AND(SUM('Баллы, оценки'!$Q23:$T23)<=2.5,(SUM('Баллы, оценки'!$Q23:$T23)>1.5)),3,2))) -> 2 | V24: 0.5 | AL24: =SUM('Баллы, оценки'!$B23:$E23,'Баллы, оценки'!$G23:$J23,'Баллы, оценки'!$L23:$O23,'Баллы, оценки'!$Q23:$T23,'Баллы, оценки'!$V23:$AF23,AH24:AK24) -> 6.5 | AM24: =32-COUNTA(B24:E24,G24:I24,L24:O24,Q24:T24,V24:AF24,AH24:AK24) -> 22 | AR24: 3 | AU24: =IF(AND('Баллы, оценки'!$AL23<=38,'Баллы, оценки'!$AL23>=31),5,IF(AND('Баллы, оценки'!$AL23<=30.9,'Баллы, оценки'!$AL23>=25),4,IF(AND('Баллы, оценки'!$AL23<=24.9,'Баллы, оценки'!$AL23>=21),3,н/а))) -> #NAME?
A25: Русинов Руслан | B25: 0.5 | C25: 0.5 | D25: 0.5 | E25: 2.5 | F25: =IF(SUM('Баллы, оценки'!$B24:$E24)>=3.5,5,IF(AND(SUM('Баллы, оценки'!$B24:$E24)>2.5,(SUM('Баллы, оценки'!$B24:$E24)<3.5)),4,IF(AND(SUM('Баллы, оценки'!$B24:$E24)<=2.5,(SUM('Баллы, оценки'!$B24:$E24)>1.5)),3,2))) -> 2 | G25: 0.5 | H25: 0.5 | I25: 0.5 | K25: =IF(SUM('Баллы, оценки'!$G24:$J24)>=3.5,5,IF(AND(SUM('Баллы, оценки'!$G24:$J24)>2.5,(SUM('Баллы, оценки'!$G24:$J24)<3.5)),4,IF(AND(SUM('Баллы, оценки'!$G24:$J24)<=2.5,(SUM('Баллы, оценки'!$G24:$J24)>1.5)),3,2))) -> 4 | P25: =IF(SUM('Баллы, оценки'!$L24:$O24)>=3.5,5,IF(AND(SUM('Баллы, оценки'!$L24:$O24)>2.5,(SUM('Баллы, оценки'!$L24:$O24)<3.5)),4,IF(AND(SUM('Баллы, оценки'!$L24:$O24)<=2.5,(SUM('Баллы, оценки'!$L24:$O24)>1.5)),3,2))) -> 2 | U25: =IF(SUM('Баллы, оценки'!$Q24:$T24)>=3.5,5,IF(AND(SUM('Баллы, оценки'!$Q24:$T24)>2.5,(SUM('Баллы, оценки'!$Q24:$T24)<3.5)),4,IF(AND(SUM('Баллы, оценки'!$Q24:$T24)<=2.5,(SUM('Баллы, оценки'!$Q24:$T24)>1.5)),3,2))) -> 2 | V25: 0.5 | AL25: =SUM('Баллы, оценки'!$B24:$E24,'Баллы, оценки'!$G24:$J24,'Баллы, оценки'!$L24:$O24,'Баллы, оценки'!$Q24:$T24,'Баллы, оценки'!$V24:$AF24,AH25:AK25) -> 6.5 | AM25: =32-COUNTA(B25:E25,G25:I25,L25:O25,Q25:T25,V25:AF25,AH25:AK25) -> 24 | AR25: 3 | AU25: =IF(AND('Баллы, оценки'!$AL24<=38,'Баллы, оценки'!$AL24>=31),5,IF(AND('Баллы, оценки'!$AL24<=30.9,'Баллы, оценки'!$AL24>=25),4,IF(AND('Баллы, оценки'!$AL24<=24.9,'Баллы, оценки'!$AL24>=21),3,н/а))) -> #NAME?
A26: Петров Никита | B26: 0.5 | C26: 0.5 | D26: 0.5 | E26: 2 | F26: =IF(SUM('Баллы, оценки'!$B22:$E22)>=3.5,5,IF(AND(SUM('Баллы, оценки'!$B22:$E22)>2.5,(SUM('Баллы, оценки'!$B22:$E22)<3.5)),4,IF(AND(SUM('Баллы, оценки'!$B22:$E22)<=2.5,(SUM('Баллы, оценки'!$B22:$E22)>1.5)),3,2))) -> 4 | G26: 0.5 | H26: 0.5 | I26: 0.5 | K26: =IF(SUM('Баллы, оценки'!$G22:$J22)>=3.5,5,IF(AND(SUM('Баллы, оценки'!$G22:$J22)>2.5,(SUM('Баллы, оценки'!$G22:$J22)<3.5)),4,IF(AND(SUM('Баллы, оценки'!$G22:$J22)<=2.5,(SUM('Баллы, оценки'!$G22:$J22)>1.5)),3,2))) -> 3 | P26: =IF(SUM('Баллы, оценки'!$L22:$O22)>=3.5,5,IF(AND(SUM('Баллы, оценки'!$L22:$O22)>2.5,(SUM('Баллы, оценки'!$L22:$O22)<3.5)),4,IF(AND(SUM('Баллы, оценки'!$L22:$O22)<=2.5,(SUM('Баллы, оценки'!$L22:$O22)>1.5)),3,2))) -> 2 | U26: =IF(SUM('Баллы, оценки'!$Q22:$T22)>=3.5,5,IF(AND(SUM('Баллы, оценки'!$Q22:$T22)>2.5,(SUM('Баллы, оценки'!$Q22:$T22)<3.5)),4,IF(AND(SUM('Баллы, оценки'!$Q22:$T22)<=2.5,(SUM('Баллы, оценки'!$Q22:$T22)>1.5)),3,2))) -> 2 | V26: 0.5 | AL26: =SUM('Баллы, оценки'!$B22:$E22,'Баллы, оценки'!$G22:$J22,'Баллы, оценки'!$L22:$O22,'Баллы, оценки'!$Q22:$T22,'Баллы, оценки'!$V22:$AF22,AH26:AK26) -> 6.5 | AM26: =32-COUNTA(B26:E26,G26:I26,L26:O26,Q26:T26,V26:AF26,AH26:AK26) -> 24 | AR26: 3 | AU26: =IF(AND('Баллы, оценки'!$AL22<=38,'Баллы, оценки'!$AL22>=31),5,IF(AND('Баллы, оценки'!$AL22<=30.9,'Баллы, оценки'!$AL22>=25),4,IF(AND('Баллы, оценки'!$AL22<=24.9,'Баллы, оценки'!$AL22>=21),3,н/а))) -> #NAME?
A27: Суворов Ярослав | B27: 0.5 | C27: 0.5 | E27: 2 | F27: =IF(SUM('Баллы, оценки'!$B29:$E29)>=3.5,5,IF(AND(SUM('Баллы, оценки'!$B29:$E29)>2.5,(SUM('Баллы, оценки'!$B29:$E29)<3.5)),4,IF(AND(SUM('Баллы, оценки'!$B29:$E29)<=2.5,(SUM('Баллы, оценки'!$B29:$E29)>1.5)),3,2))) -> 2 | G27: 0.5 | H27: 0.5 | I27: 0.5 | K27: =IF(SUM('Баллы, оценки'!$G29:$J29)>=3.5,5,IF(AND(SUM('Баллы, оценки'!$G29:$J29)>2.5,(SUM('Баллы, оценки'!$G29:$J29)<3.5)),4,IF(AND(SUM('Баллы, оценки'!$G29:$J29)<=2.5,(SUM('Баллы, оценки'!$G29:$J29)>1.5)),3,2))) -> 2 | P27: =IF(SUM('Баллы, оценки'!$L29:$O29)>=3.5,5,IF(AND(SUM('Баллы, оценки'!$L29:$O29)>2.5,(SUM('Баллы, оценки'!$L29:$O29)<3.5)),4,IF(AND(SUM('Баллы, оценки'!$L29:$O29)<=2.5,(SUM('Баллы, оценки'!$L29:$O29)>1.5)),3,2))) -> 2 | U27: =IF(SUM('Баллы, оценки'!$Q29:$T29)>=3.5,5,IF(AND(SUM('Баллы, оценки'!$Q29:$T29)>2.5,(SUM('Баллы, оценки'!$Q29:$T29)<3.5)),4,IF(AND(SUM('Баллы, оценки'!$Q29:$T29)<=2.5,(SUM('Баллы, оценки'!$Q29:$T29)>1.5)),3,2))) -> 2 | V27: 0.5 | AL27: =SUM('Баллы, оценки'!$B29:$E29,'Баллы, оценки'!$G29:$J29,'Баллы, оценки'!$L29:$O29,'Баллы, оценки'!$Q29:$T29,'Баллы, оценки'!$V29:$AF29,AH27:AK27) -> 2.5 | AM27: =32-COUNTA(B27:E27,G27:I27,L27:O27,Q27:T27,V27:AF27,AH27:AK27) -> 25 | AR27: 3 | AU27: =IF(AND('Баллы, оценки'!$AL29<=38,'Баллы, оценки'!$AL29>=31),5,IF(AND('Баллы, оценки'!$AL29<=30.9,'Баллы, оценки'!$AL29>=25),4,IF(AND('Баллы, оценки'!$AL29<=24.9,'Баллы, оценки'!$AL29>=21),3,н/а))) -> #NAME?
A28: Шапляк Максим | B28: 0.5 | C28: 0.5 | D28: 0.5 | E28: 2 | F28: =IF(SUM('Баллы, оценки'!$B30:$E30)>=3.5,5,IF(AND(SUM('Баллы, оценки'!$B30:$E30)>2.5,(SUM('Баллы, оценки'!$B30:$E30)<3.5)),4,IF(AND(SUM('Баллы, оценки'!$B30:$E30)<=2.5,(SUM('Баллы, оценки'!$B30:$E30)>1.5)),3,2))) -> 2 | G28: 0.5 | H28: 0.5 | I28: 0.5 | K28: =IF(SUM('Баллы, оценки'!$G30:$J30)>=3.5,5,IF(AND(SUM('Баллы, оценки'!$G30:$J30)>2.5,(SUM('Баллы, оценки'!$G30:$J30)<3.5)),4,IF(AND(SUM('Баллы, оценки'!$G30:$J30)<=2.5,(SUM('Баллы, оценки'!$G30:$J30)>1.5)),3,2))) -> 2 | P28: =IF(SUM('Баллы, оценки'!$L30:$O30)>=3.5,5,IF(AND(SUM('Баллы, оценки'!$L30:$O30)>2.5,(SUM('Баллы, оценки'!$L30:$O30)<3.5)),4,IF(AND(SUM('Баллы, оценки'!$L30:$O30)<=2.5,(SUM('Баллы, оценки'!$L30:$O30)>1.5)),3,2))) -> 2 | U28: =IF(SUM('Баллы, оценки'!$Q30:$T30)>=3.5,5,IF(AND(SUM('Баллы, оценки'!$Q30:$T30)>2.5,(SUM('Баллы, оценки'!$Q30:$T30)<3.5)),4,IF(AND(SUM('Баллы, оценки'!$Q30:$T30)<=2.5,(SUM('Баллы, оценки'!$Q30:$T30)>1.5)),3,2))) -> 2 | AL28: =SUM('Баллы, оценки'!$B30:$E30,'Баллы, оценки'!$G30:$J30,'Баллы, оценки'!$L30:$O30,'Баллы, оценки'!$Q30:$T30,'Баллы, оценки'!$V30:$AF30,AH28:AK28) -> 2 | AM28: =32-COUNTA(B28:E28,G28:I28,L28:O28,Q28:T28,V28:AF28,AH28:AK28) -> 25 | AR28: 4 | AU28: =IF(AND('Баллы, оценки'!$AL30<=38,'Баллы, оценки'!$AL30>=31),5,IF(AND('Баллы, оценки'!$AL30<=30.9,'Баллы, оценки'!$AL30>=25),4,IF(AND('Баллы, оценки'!$AL30<=24.9,'Баллы, оценки'!$AL30>=21),3,н/а))) -> #NAME?
A29: Липатов Сергей | B29: 0.5 | C29: 0.5 | D29: 0.5 | F29: =IF(SUM('Баллы, оценки'!$B17:$E17)>=3.5,5,IF(AND(SUM('Баллы, оценки'!$B17:$E17)>2.5,(SUM('Баллы, оценки'!$B17:$E17)<3.5)),4,IF(AND(SUM('Баллы, оценки'!$B17:$E17)<=2.5,(SUM('Баллы, оценки'!$B17:$E17)>1.5)),3,2))) -> 5 | H29: 0.5 | I29: 0.5 | K29: =IF(SUM('Баллы, оценки'!$G17:$J17)>=3.5,5,IF(AND(SUM('Баллы, оценки'!$G17:$J17)>2.5,(SUM('Баллы, оценки'!$G17:$J17)<3.5)),4,IF(AND(SUM('Баллы, оценки'!$G17:$J17)<=2.5,(SUM('Баллы, оценки'!$G17:$J17)>1.5)),3,2))) -> 3 | P29: =IF(SUM('Баллы, оценки'!$L17:$O17)>=3.5,5,IF(AND(SUM('Баллы, оценки'!$L17:$O17)>2.5,(SUM('Баллы, оценки'!$L17:$O17)<3.5)),4,IF(AND(SUM('Баллы, оценки'!$L17:$O17)<=2.5,(SUM('Баллы, оценки'!$L17:$O17)>1.5)),3,2))) -> 2 | U29: =IF(SUM('Баллы, оценки'!$Q17:$T17)>=3.5,5,IF(AND(SUM('Баллы, оценки'!$Q17:$T17)>2.5,(SUM('Баллы, оценки'!$Q17:$T17)<3.5)),4,IF(AND(SUM('Баллы, оценки'!$Q17:$T17)<=2.5,(SUM('Баллы, оценки'!$Q17:$T17)>1.5)),3,2))) -> 2 | AL29: =SUM('Баллы, оценки'!$B17:$E17,'Баллы, оценки'!$G17:$J17,'Баллы, оценки'!$L17:$O17,'Баллы, оценки'!$Q17:$T17,'Баллы, оценки'!$V17:$AF17,AH29:AK29) -> 8 | AM29: =32-COUNTA(B29:E29,G29:I29,L29:O29,Q29:T29,V29:AF29,AH29:AK29) -> 27 | AU29: =IF(AND('Баллы, оценки'!$AL17<=38,'Баллы, оценки'!$AL17>=31),5,IF(AND('Баллы, оценки'!$AL17<=30.9,'Баллы, оценки'!$AL17>=25),4,IF(AND('Баллы, оценки'!$AL17<=24.9,'Баллы, оценки'!$AL17>=21),3,н/а))) -> #NAME?
A30: Веселкин Илья | B30: 0.5 | F30: =IF(SUM('Баллы, оценки'!$B6:$E6)>=3.5,5,IF(AND(SUM('Баллы, оценки'!$B6:$E6)>2.5,(SUM('Баллы, оценки'!$B6:$E6)<3.5)),4,IF(AND(SUM('Баллы, оценки'!$B6:$E6)<=2.5,(SUM('Баллы, оценки'!$B6:$E6)>1.5)),3,2))) -> 5 | G30: 0.5 | H30: 0.5 | K30: =IF(SUM('Баллы, оценки'!$G6:$J6)>=3.5,5,IF(AND(SUM('Баллы, оценки'!$G6:$J6)>2.5,(SUM('Баллы, оценки'!$G6:$J6)<3.5)),4,IF(AND(SUM('Баллы, оценки'!$G6:$J6)<=2.5,(SUM('Баллы, оценки'!$G6:$J6)>1.5)),3,2))) -> 5 | P30: =IF(SUM('Баллы, оценки'!$L6:$O6)>=3.5,5,IF(AND(SUM('Баллы, оценки'!$L6:$O6)>2.5,(SUM('Баллы, оценки'!$L6:$O6)<3.5)),4,IF(AND(SUM('Баллы, оценки'!$L6:$O6)<=2.5,(SUM('Баллы, оценки'!$L6:$O6)>1.5)),3,2))) -> 2 | U30: =IF(SUM('Баллы, оценки'!$Q6:$T6)>=3.5,5,IF(AND(SUM('Баллы, оценки'!$Q6:$T6)>2.5,(SUM('Баллы, оценки'!$Q6:$T6)<3.5)),4,IF(AND(SUM('Баллы, оценки'!$Q6:$T6)<=2.5,(SUM('Баллы, оценки'!$Q6:$T6)>1.5)),3,2))) -> 2 | V30: 0.5 | AL30: =SUM('Баллы, оценки'!$B6:$E6,'Баллы, оценки'!$G6:$J6,'Баллы, оценки'!$L6:$O6,'Баллы, оценки'!$Q6:$T6,'Баллы, оценки'!$V6:$AF6,AH30:AK30) -> 9.5 | AM30: =32-COUNTA(B30:E30,G30:I30,L30:O30,Q30:T30,V30:AF30,AH30:AK30) -> 28 | AU30: =IF(AND('Баллы, оценки'!$AL6<=38,'Баллы, оценки'!$AL6>=31),5,IF(AND('Баллы, оценки'!$AL6<=30.9,'Баллы, оценки'!$AL6>=25),4,IF(AND('Баллы, оценки'!$AL6<=24.9,'Баллы, оценки'!$AL6>=21),3,н/а))) -> #NAME?
B31: =COUNTA(B3:B30) -> 26 | C31: =COUNTA(C3:C30) -> 27 | D31: =COUNTA(D3:D30) -> 21 | E31: =COUNTA(E3:E30) -> 24 | G31: =COUNTA(G3:G30) -> 26 | H31: =COUNTA(H3:H30) -> 26 | I31: =COUNTA(I3:I30) -> 25 | J31: =COUNTA(J3:J30) -> 22 | L31: =COUNTA(L3:L30) -> 21 | M31: =COUNTA(M3:M30) -> 21 | N31: =COUNTA(N3:N30) -> 22 | O31: =COUNTA(O3:O30) -> 0 | Q31: =COUNTA(Q3:Q30) -> 0 | R31: =COUNTA(R3:R30) -> 0 | S31: =COUNTA(S3:S30) -> 0 | T31: =COUNTA(T3:T30) -> 0 | V31: ПРАКТИЧЕСКИЕ РАБОТЫ | AC31: ЛАБОРАТОРНЫЕ РАБОТЫ
A32: Итоговый балл и оценка:
A33: ОТЛИЧНО (оценка 5) | B33: 0.5 | C33: 0.5 | D33: 0.5 | E33: 2 | F33: =IF(SUM('Баллы, оценки'!$B33:$E33)>=3.5,5,IF(AND(SUM('Баллы, оценки'!$B33:$E33)>2.5,(SUM('Баллы, оценки'!$B33:$E33)<3.5)),4,IF(AND(SUM('Баллы, оценки'!$B33:$E33)<=2.5,(SUM('Баллы, оценки'!$B33:$E33)>1.5)),3,2))) -> 5 | G33: 0.5 | H33: 0.5 | I33: 0.5 | J33: 2 | K33: =IF(SUM('Баллы, оценки'!$G33:$J33)>=3.5,5,IF(AND(SUM('Баллы, оценки'!$G33:$J33)>2.5,(SUM('Баллы, оценки'!$G33:$J33)<3.5)),4,IF(AND(SUM('Баллы, оценки'!$G33:$J33)<=2.5,(SUM('Баллы, оценки'!$G33:$J33)>1.5)),3,2))) -> 5 | L33: 0.5 | M33: 0.5 | N33: 0.5 | O33: 2 | P33: =IF(SUM('Баллы, оценки'!$L33:$O33)>=3.5,5,IF(AND(SUM('Баллы, оценки'!$L33:$O33)>2.5,(SUM('Баллы, оценки'!$L33:$O33)<3.5)),4,IF(AND(SUM('Баллы, оценки'!$L33:$O33)<=2.5,(SUM('Баллы, оценки'!$L33:$O33)>1.5)),3,2))) -> 5 | Q33: 0.5 | R33: 0.5 | S33: 0.5 | T33: 2 | U33: =IF(SUM('Баллы, оценки'!$Q33:$T33)>=3.5,5,IF(AND(SUM('Баллы, оценки'!$Q33:$T33)>2.5,(SUM('Баллы, оценки'!$Q33:$T33)<3.5)),4,IF(AND(SUM('Баллы, оценки'!$Q33:$T33)<=2.5,(SUM('Баллы, оценки'!$Q33:$T33)>1.5)),3,2))) -> 5 | V33: 2 | W33: 2 | X33: 2 | Y33: 2 | Z33: 2 | AA33: 2 | AB33: 2 | AC33: 2 | AD33: 2 | AE33: 2 | AF33: 2 | AG33: =SUM('Баллы, оценки'!$B33:$E33,'Баллы, оценки'!$G33:$J33,'Баллы, оценки'!$L33:$O33,'Баллы, оценки'!$Q33:$T33,'Баллы, оценки'!$V33:$AF33) -> 36 | AH33: от 38 до 31 | AU33: 5
A34: ХОРОШО (оценка 4) | B34: 0.5 | C34: 0.5 | D34: 0.5 | E34: 1.5 | F34: =IF(SUM('Баллы, оценки'!$B34:$E34)>=3.5,5,IF(AND(SUM('Баллы, оценки'!$B34:$E34)>2.5,(SUM('Баллы, оценки'!$B34:$E34)<3.5)),4,IF(AND(SUM('Баллы, оценки'!$B34:$E34)<=2.5,(SUM('Баллы, оценки'!$B34:$E34)>1.5)),3,2))) -> 4 | G34: 0.5 | H34: 0.5 | I34: 0.5 | J34: 1.5 | K34: =IF(SUM('Баллы, оценки'!$G34:$J34)>=3.5,5,IF(AND(SUM('Баллы, оценки'!$G34:$J34)>2.5,(SUM('Баллы, оценки'!$G34:$J34)<3.5)),4,IF(AND(SUM('Баллы, оценки'!$G34:$J34)<=2.5,(SUM('Баллы, оценки'!$G34:$J34)>1.5)),3,2))) -> 4 | L34: 0.5 | M34: 0.5 | N34: 0.5 | O34: 1.5 | P34: =IF(SUM('Баллы, оценки'!$L34:$O34)>=3.5,5,IF(AND(SUM('Баллы, оценки'!$L34:$O34)>2.5,(SUM('Баллы, оценки'!$L34:$O34)<3.5)),4,IF(AND(SUM('Баллы, оценки'!$L34:$O34)<=2.5,(SUM('Баллы, оценки'!$L34:$O34)>1.5)),3,2))) -> 4 | Q34: 0.5 | R34: 0.5 | S34: 0.5 | T34: 1.5 | U34: =IF(SUM('Баллы, оценки'!$Q34:$T34)>=3.5,5,IF(AND(SUM('Баллы, оценки'!$Q34:$T34)>2.5,(SUM('Баллы, оценки'!$Q34:$T34)<3.5)),4,IF(AND(SUM('Баллы, оценки'!$Q34:$T34)<=2.5,(SUM('Баллы, оценки'!$Q34:$T34)>1.5)),3,2))) -> 4 | V34: 1.5 | W34: 1.5 | X34: 1.5 | Y34: 1.5 | Z34: 1.5 | AA34: 1.5 | AB34: 1.5 | AC34: 1.5 | AD34: 1.5 | AE34: 1.5 | AF34: 1.5 | AG34: =SUM('Баллы, оценки'!$B34:$E34,'Баллы, оценки'!$G34:$J34,'Баллы, оценки'!$L34:$O34,'Баллы, оценки'!$Q34:$T34,'Баллы, оценки'!$V34:$AF34) -> 28.5 | AH34: от 30,9 до 25 | AU34: 4
A35: УДОВЛЕТВ. (оценка 3) | B35: 0.5 | C35: 0.5 | D35: 0.5 | E35: 1 | F35: =IF(SUM('Баллы, оценки'!$B35:$E35)>=3.5,5,IF(AND(SUM('Баллы, оценки'!$B35:$E35)>2.5,(SUM('Баллы, оценки'!$B35:$E35)<3.5)),4,IF(AND(SUM('Баллы, оценки'!$B35:$E35)<=2.5,(SUM('Баллы, оценки'!$B35:$E35)>1.5)),3,2))) -> 3 | G35: 0.5 | H35: 0.5 | I35: 0.5 | J35: 1 | K35: =IF(SUM('Баллы, оценки'!$G35:$J35)>=3.5,5,IF(AND(SUM('Баллы, оценки'!$G35:$J35)>2.5,(SUM('Баллы, оценки'!$G35:$J35)<3.5)),4,IF(AND(SUM('Баллы, оценки'!$G35:$J35)<=2.5,(SUM('Баллы, оценки'!$G35:$J35)>1.5)),3,2))) -> 3 | L35: 0.5 | M35: 0.5 | N35: 0.5 | O35: 1 | P35: =IF(SUM('Баллы, оценки'!$L35:$O35)>=3.5,5,IF(AND(SUM('Баллы, оценки'!$L35:$O35)>2.5,(SUM('Баллы, оценки'!$L35:$O35)<3.5)),4,IF(AND(SUM('Баллы, оценки'!$L35:$O35)<=2.5,(SUM('Баллы, оценки'!$L35:$O35)>1.5)),3,2))) -> 3 | Q35: 0.5 | R35: 0.5 | S35: 0.5 | T35: 1 | U35: =IF(SUM('Баллы, оценки'!$Q35:$T35)>=3.5,5,IF(AND(SUM('Баллы, оценки'!$Q35:$T35)>2.5,(SUM('Баллы, оценки'!$Q35:$T35)<3.5)),4,IF(AND(SUM('Баллы, оценки'!$Q35:$T35)<=2.5,(SUM('Баллы, оценки'!$Q35:$T35)>1.5)),3,2))) -> 3 | V35: 1 | W35: 1 | X35: 1 | Y35: 1 | Z35: 1 | AA35: 1 | AB35: 1 | AC35: 1 | AD35: 1 | AE35: 1 | AF35: 1 | AG35: =SUM('Баллы, оценки'!$B35:$E35,'Баллы, оценки'!$G35:$J35,'Баллы, оценки'!$L35:$O35,'Баллы, оценки'!$Q35:$T35,'Баллы, оценки'!$V35:$AF35) -> 21 | AH35: от 24,9 до 21 | AU35: 3
A36: Промежуточный балл:
A37: 3,5 Балла >= оценка 5
A38: 2,5 Б >= оценка 4 < 3,5 Б
A39: 1 Б > оценка 3 < 2,5 Б
A41: Комментарии по баллам в таблице
...

Sheet Чек-лист
A1: Вопросы уроков (1-3) | B1: ДЗ_1-3 по учебнику | C1: ИТОГ (4 урок) | D1: Вопросы уроков (5-7) | E1: ДЗ_5-7 по учебнику | F1: ИТОГ (8 урок) | G1: Вопросы уроков (9-11) | H1: ДЗ_9-11 по учебнику | I1: ИТОГ (12 урок) | J1: Вопросы уроков (13-15) | K1: ДЗ_13-15 по учебнику | L1: ИТОГ (16 урок) | M1: Темы Практических работ | N1: Темы Лабораторных работ
A2: 1. Введение в теорию Баз данных, СУБД | B2: стр. 5-8 | C2: Вопросы по учебнику | D2: 5. Нормализация баз данных | E2: стр.23-27 | F2: Контрольные вопросы по учебнику стр. 35-37 | G2: 9. Основные характеристики и возможности СУБД MS Access | H2: стр. 38-42 | I2: Контрольные вопросы по учебнику стр. 94-95 (с 1-18) | J2: 13. Разработка БД в СУБД MS Access: формы (элементы управления), отчеты | K2: стр.78-84 | L2: Контрольные вопросы по учебнику стр. 94-95 (с 18-26) | M2: Практическая работа №1 ER-модель, язык инфологического моделирования. Практическая работа №1Проектирование по темам: "Электронная ведомость", процесс нормализации | N2: Лабораторная работа №1 Разработка вариативной БД, ER-модель, основные объекты, схема данных
A3: Понятие предметной области. ER-модель | C3: ТЕСТ | D3: Нормальные формы: 1НФ, 2НФ, 3НФ | F3: ТЕСТ | G3: Основные компоненты СУБД MS Access: таблица, запрос, форма, отчет, макрос | I3: ТЕСТ | J3: Условия отбора записей, сортировка и фильтрация | L3: ТЕСТ | M3: Практическая работа №2 Работа в среде Access. Разработка БД. Схема данных Практическая работа №2 Проектирование по темам: "Поликлиника", "Библиотека", процесс нормализации | N3: Лабораторная работа №2 Разработка информативных запросов к вариативной БД
A4: 2. Состав информационной модели: концептуальная, логическая, физическая модели | B4: стр. 9-11 | C4: Самостоят. работа | D4: 6. Основы реляционной алгебры | E4: стр. 17-22 | F4: Самостоят. работа | G4: 10. Типы данных базы данных, способы создания таблиц, импорт БД | H4: стр. 42-47 | I4: Самостоят. работа | J4: 14. Элементы языка SQL, запросы в форме SQL | K4: стр. 64-69 | L4: Самостоят. работа | M4: Практическая работа №3 Импорт данных при разработке БД Access Практическая работа №3 Проектирование по темам: "Продажа товара", "Сад" (excel), нормальные формы | N4: Лабораторная работа №3 Разработка форм, отчетов по вариативной БД
A5: Знакомство с СУБД Access, БД "Выставка собак", "Мой сад". Словарь данных | C5: Работа за ПК, Словарь данных | D5: Запросы к базе данных | F5: Работа за ПК, анализ БД, проект БД | G5: Разработка БД в СУБД MS Access: таблицы, запросы | H5: стр. 46-53 | I5: Работа за ПК, разработка БД | J5: Операторы языка SQL | L5: Работа за ПК, разработка запросов | M5: Практическая работа №4 Работа в среде Access. Запросы Практическая работа №4 Проектирование информационных запросов по темам выше, бланк запроса | N5: Лабораторная работа №4 Разработка отчетной документации. Сдача вариативной работы
A6: 3. Три типа логической модели данных: иерархическая, сетевая, реляционная | B6: стр.11-17 | D6: 7. Этапы проектирования БД | E6: стр. 27-35 | G6: 11. Обработка даных в БД. Бланк запрос. | H6: стр.54-63 | J6: 15. Организация запросов в форме SQL | K6: стр. 69-75 | M6: Практическая работа №5 Разработка запросов различного вида Практическая работа №5 Проектирование информационных запросов, интерфейс логического выполнения функции БД по темам выше
A7: Реляционная модель: таблица, первичный и внешний ключ, схема данных | D7: Проектирование Схемы данных: атрибуты, первичные и внешние ключи, 3НФ | G7: Виды запросов: выборка с условием, выборка с параметром, итоговый, вычисляемый, перекрестный | J7: Синтаксис оператора Select | M7: Практическая работа №6 Разработка форм: Главная, основная, подчиненная Практическая работа №6 Проектирование отчетов, интерфейс приложения по темам выше
M8: Практическая работа №7 Работа с запросами в режиме SQL Практическая работа №7 Проектирование информационных запросов в режиме SQL по темам выше
A11: Учебник: А.В.Кузин, В.М. Демин "Разработка баз данных в системе MS Access" | M11: Обязательная предварительная подготовка к практическим заданиям, смотрим в moodle | N11: Обязательная предварительная подготовка к лабораторным заданиям, смотрим в moodle

Sheet Даты_темы
C1: Группа: ИСП 25А. 1 семестр | G1: кол-во оценок
C2: Дисциплина: Основы проектирования БД | F2: итог_оценка за 4 урока | G2: 4
C3: ФИО преподавателя: Ольга Михайловна Селиверстова | F3: практическая работа | G3: 7
B4: № | F4: лабораторная работа | G4: 4
B5: Урока | C5: Дата | D5: Тема занятия | F5: теория
A6: 1 | B6: 1 | C6: 46270 | D6: Введение в теорию Баз данных, СУБД | G6: =SUM(G2:G5) -> 15
D7: Понятие предметной области. ER-модель
A8: 2 | B8: 2 | C8: 45907 | D8: Состав информационной модели: концептуальная, логическая, физическая модели | G8: 1 подгр на уроке | H8: 2 подгр 2 пара четверг
D9: Знакомство с СУБД Access, БД "Выставка собак", "Мой сад". Словарь данных | F9: Лабораторная работа №1 | G9: 46307 | H9: 46310
A10: 3 | B10: 3 | C10: 45912 | D10: Три типа логической модели данных: иерархическая, сетевая, реляционная | F10: Лабораторная работа №2 | G10: 46314 | H10: 46317
D11: Реляционная модель: таблица, первичный и внешний ключ, схема данных, типы данных | F11: Лабораторная работа №3 | G11: 46321 | H11: 46324
A12: 4 | B12: 4 | C12: 45914 | D12: Тестирование. Анализ и описание предлагаемой БД, составление Словаря данных | F12: Лабораторная работа №4 | G12: 46328 | H12: 46331
D13: Язык инфологического моделирования
A14: 5 | B14: 17 | C14: 45919 | D14: Практическая работа №1 ER-модель, язык инфологического моделирования.
D15: Практическая работа №1 Проектирование по теме "Библиотека"
A16: 6 | B16: 5 | C16: 45921 | D16: Нормализация баз данных
D17: Нормальные формы: 1НФ, 2НФ, 3НФ
A18: 7 | B18: 6 | C18: 45923 | D18: Нормализация баз данных
D19: Нормальные формы: 1НФ, 2НФ, 3НФ
A20: 8 | B20: 7 | C20: 45956 | D20: Основы реляционной алгебры
D21: Запросы к базе данных
A22: 9 | B22: 8 | C22: 45933 | D22: Этапы проектирования БД
D23: Проектирование Схемы данных: атрибуты, первичные и внешние ключи, 3НФ
A24: 10 | B24: 9 | C24: 45935 | D24: Операции над отношениями
D25: Разбор примера выполнения вариативного задания/ Тестирование Типы данных базы данных, способы создания таблиц, импорт БД
A26: 11 | B26: 10 | C26: 45935 | D26: Основные характеристики и возможности СУБД MS Access
D27: Основные компоненты СУБД MS Access: таблица, запрос, форма, отчет, макрос
A28: 12 | B28: 11 | C28: 45940 | D28: Обработка даных в БД. Бланк запрос.
D29: Разработка БД в СУБД MS Access: таблицы, запросы
A30: 13 | B30: 24 | C30: 12.10.-15/10 | D30: Лабораторная работа №1 Разработка вариативной БД, ER-модель, основные объекты, схема данных
C31: 46310 | D31: Лабораторная работа №1 Разработка вариативной БД, ER-модель, основные объекты, схема данных
A32: 14 | B32: 18 | C32: 45947 | D32: Практическая работа №2 Работа в среде Access. Разработка БД. Схема данных
D33: Практическая работа №2 Проектирование по темам: "Поликлиника", "Библиотека", процесс нормализации
A34: 15 | B34: 25 | C34: 45949 | D34: Лабораторная работа №2 Разработка информативных запросов к вариативной БД
C35: 46317 | D35: Лабораторная работа №2 Разработка информативных запросов к вариативной БД
A36: 16 | B36: 19 | C36: 45954 | D36: Практическая работа №3 Импорт данных при разработке БД Access нормальные формы
D37: Практическая работа №3 Проектирование по темам: "Продажа товара", "Сад" (excel), нормальные формы
A38: 17 | B38: 26 | C38: 45956 | D38: Лабораторная работа №3 Разработка форм, отчетов по вариативной БД
C39: 46324 | D39: Лабораторная работа №3 Разработка форм, отчетов по вариативной БД
A40: 18 | B40: 12 | C40: 45961 | D40: Разработка БД разными способами
...
